Workbook

Sheet README
A1: Ekologia - instrukcja do workbooka
A3: Ten workbook wspiera dwa ćwiczenia: poziom zanieczyszczenia powietrza oraz parametry fizykochemiczne gleby.
A4: Kolory: niebieski = dane wejściowe, szary = stałe, jasnoszary = formuły, żółty = uwagi i ostrzeżenia.
A5: Powietrze: wpisz alias zanieczyszczenia, nazwę, jednostkę i 10 kolejnych dni danych dla 3 stacji.
A6: Gleba: wpisz surowe pomiary pH, objętości i stężenia. Arkusz wynikowy obliczy Hh, S, T, Mz, Hh_ha, CaO i CaCO3.
A8: Wzory zaimplementowane w workbooku:
A9: Psi = Σ(Cx / D24x)
A10: Tau = Σ(Cx * alpha_t)
A11: Hh = V * c * 10 * k
A12: Mz = p * h * rho
A13: Hh_ha = Hh * Mz / 100
A14: CaO = Hh_ha * 0,028
... A20: Brakujących limitów i współczynników toksyczności nie uzupełniono automatycznie - workbook pokazuje wtedy ostrzeżenia.

Sheet Powietrze_Dane
A1: Powietrze - dane wejściowe
A2: Data początkowa | B2: 46082
A3: Data końcowa | B3: =B2+9
A4: Godzina pomiaru | B4: 08:00
A6: Typ obszaru | B6: Typ punktu | C6: Województwo | D6: Adres | E6: Nazwa stacji
A7: miejska | B7: komunikacyjna | C7: dolnośląskie | D7: ul. Wyb. J. Conrada-Korzeniowskiego 18, Wrocław | E7: Stacja Wrocław - śródmieście
A8: podmiejska | B8: tło | C8: dolnośląskie | D8: ul. Parkowa 3, Długołęka | E8: Stacja Długołęka
A9: pozamiejska | B9: tło | C9: dolnośląskie | D9: Jeleniów 12, teren referencyjny | E9: Stacja Jeleniów
A12: Zanieczyszczenie 1 | B12: O3 | C12: ozon | D12: µg/m3 | E12: Wprowadź 10 kolejnych dni danych
A13: Data | B13: Miejska | C13: Podmiejska | D13: Pozamiejska
A14: =$B$2+0 | B14: 65 | C14: 58 | D14: 50
A15: =$B$2+1 | B15: 72 | C15: 60 | D15: 53
A16: =$B$2+2 | B16: 80 | C16: 66 | D16: 57
A17: =$B$2+3 | B17: 78 | C17: 69 | D17: 61
A18: =$B$2+4 | B18: 74 | C18: 67 | D18: 59
A19: =$B$2+5 | B19: 70 | C19: 62 | D19: 56
A20: =$B$2+6 | B20: 68 | C20: 60 | D20: 54
A21: =$B$2+7 | B21: 66 | C21: 59 | D21: 52
A22: =$B$2+8 | B22: 64 | C22: 56 | D22: 49
A23: =$B$2+9 | B23: 61 | C23: 54 | D23: 47
A24: Godzina pomiaru | B24: =$B$4
A27: Zanieczyszczenie 2 | B27: SO2 | C27: ditlenek siarki | D27: µg/m3 | E27: Wprowadź 10 kolejnych dni danych
A28: Data | B28: Miejska | C28: Podmiejska | D28: Pozamiejska
A29: =$B$2+0 | B29: 21 | C29: 17 | D29: 13
A30: =$B$2+1 | B30: 22 | C30: 18 | D30: 14
A31: =$B$2+2 | B31: 23 | C31: 19 | D31: 15
A32: =$B$2+3 | B32: 24 | C32: 20 | D32: 15
A33: =$B$2+4 | B33: 24 | C33: 20 | D33: 16
A34: =$B$2+5 | B34: 25 | C34: 19 | D34: 15
A35: =$B$2+6 | B35: 23 | C35: 18 | D35: 14
A36: =$B$2+7 | B36: 22 | C36: 18 | D36: 14
A37: =$B$2+8 | B37: 21 | C37: 17 | D37: 13
A38: =$B$2+9 | B38: 20 | C38: 16 | D38: 13
A39: Godzina pomiaru | B39: =$B$4
A42: Zanieczyszczenie 3 | B42: NO2 | C42: ditlenek azotu | D42: µg/m3 | E42: Wprowadź 10 kolejnych dni danych
A43: Data | B43: Miejska | C43: Podmiejska | D43: Pozamiejska
A44: =$B$2+0 | B44: 88 | C44: 61 | D44: 39
A45: =$B$2+1 | B45: 92 | C45: 64 | D45: 41
A46: =$B$2+2 | B46: 96 | C46: 67 | D46: 43
A47: =$B$2+3 | B47: 101 | C47: 69 | D47: 45
...

Sheet Powietrze_Mapowanie
A1: Powietrze - mapowanie
A3: Zanieczyszczenie | B3: Współczynnik toksyczności | D3: Zanieczyszczenie | E3: Współczynnik toksyczności | G3: Alias | H3: Nazwa wyświetlana | I3: Nazwa do limitu | J3: Nazwa do toksyczności | K3: Jednostka
A4: benzen | B4: 5 | D4: tlenek siarki IV | E4: 1 | G4: O3 | H4: ozon | I4: ozon | J4: ozon | K4: µg/m3
A5: ditlenek azotu | B5: 200 | D5: tlenek węgla II | E5: 0.5 | G5: CO | H5: tlenek węgla | I5: tlenek węgla | J5: tlenek węgla II | K5: µg/m3
A6: ditlenek siarki | B6: 125 | D6: tlenki azotu | E6: 2 | G6: NO2 | H6: ditlenek azotu | I6: ditlenek azotu | J6: tlenki azotu | K6: µg/m3
A7: ozon | B7: 120 | D7: ozon | E7: 10.3 | G7: SO2 | H7: ditlenek siarki | I7: ditlenek siarki | J7: tlenek siarki IV | K7: µg/m3
A8: pył zawieszony PM10 | B8: 50 | D8: pył zawieszony | E8: 2.9 | G8: PM10 | H8: pył zawieszony PM10 | I8: pył zawieszony PM10 | J8: pył zawieszony | K8: µg/m3
A9: tlenek węgla | B9: 10000 | D9: chrom | E9: 160 | G9: BENZEN | H9: benzen | I9: benzen | K9: µg/m3
D10: cynk | E10: 16.9 | G10: NOx | H10: tlenki azotu | J10: tlenki azotu | K10: µg/m3
D11: kadm | E11: 640 | G11: CHROM | H11: chrom | J11: chrom | K11: µg/m3
D12: miedź | E12: 106.7 | G12: CYNK | H12: cynk | J12: cynk | K12: µg/m3
D13: ołów | E13: 320 | G13: KADM | H13: kadm | J13: kadm | K13: µg/m3
D14: żelazo | E14: 2 | G14: MIEDŹ | H14: miedź | J14: miedź | K14: µg/m3
G15: OŁÓW | H15: ołów | J15: ołów | K15: µg/m3
G16: ŻELAZO | H16: żelazo | J16: żelazo | K16: µg/m3

Sheet Powietrze_Wyniki
A1: Powietrze - wyniki
A2: Stacja | B2: Psi | C2: Interpretacja Psi | D2: Tau | E2: Interpretacja Tau | F2: Przekroczenia średniej | G2: Przekroczenia maksimum | H2: Pominięcia z Psi | I2: Pominięcia z Tau
A3: miejska | B3: =SUMIF($B$10:$B$27,A3,$O$10:$O$27) | C3: =IF(B3="","Brak danych",IF(B3<=1,"jakość powietrza zadowalająca","wyższa wartość oznacza gorszą jakość powietrza")) | D3: =SUMIF($B$10:$B$27,A3,$P$10:$P$27) | E3: =IF(D3="","Brak danych","niższa wartość oznacza lepszą jakość powietrza") | F3: =COUNTIFS($B$10:$B$27,A3,$M$10:$M$27,"TAK") | G3: =COUNTIFS($B$10:$B$27,A3,$N$10:$N$27,"TAK") | H3: =COUNTIFS($B$10:$B$27,A3,$Q$10:$Q$27,"<>") | I3: =COUNTIFS($B$10:$B$27,A3,$R$10:$R$27,"<>")
A4: podmiejska | B4: =SUMIF($B$10:$B$27,A4,$O$10:$O$27) | C4: =IF(B4="","Brak danych",IF(B4<=1,"jakość powietrza zadowalająca","wyższa wartość oznacza gorszą jakość powietrza")) | D4: =SUMIF($B$10:$B$27,A4,$P$10:$P$27) | E4: =IF(D4="","Brak danych","niższa wartość oznacza lepszą jakość powietrza") | F4: =COUNTIFS($B$10:$B$27,A4,$M$10:$M$27,"TAK") | G4: =COUNTIFS($B$10:$B$27,A4,$N$10:$N$27,"TAK") | H4: =COUNTIFS($B$10:$B$27,A4,$Q$10:$Q$27,"<>") | I4: =COUNTIFS($B$10:$B$27,A4,$R$10:$R$27,"<>")
A5: pozamiejska | B5: =SUMIF($B$10:$B$27,A5,$O$10:$O$27) | C5: =IF(B5="","Brak danych",IF(B5<=1,"jakość powietrza zadowalająca","wyższa wartość oznacza gorszą jakość powietrza")) | D5: =SUMIF($B$10:$B$27,A5,$P$10:$P$27) | E5: =IF(D5="","Brak danych","niższa wartość oznacza lepszą jakość powietrza") | F5: =COUNTIFS($B$10:$B$27,A5,$M$10:$M$27,"TAK") | G5: =COUNTIFS($B$10:$B$27,A5,$N$10:$N$27,"TAK") | H5: =COUNTIFS($B$10:$B$27,A5,$Q$10:$Q$27,"<>") | I5: =COUNTIFS($B$10:$B$27,A5,$R$10:$R$27,"<>")
A9: Slot | B9: Stacja | C9: Alias | D9: Nazwa | E9: Jednostka | F9: Nazwa do limitu | G9: Limit D24 | H9: Nazwa do toksyczności | I9: Wsp. toksyczności | J9: MIN | K9: ŚREDNIA | L9: MAX | M9: Średnia > limit | N9: MAX > limit | O9: Składnik Psi | P9: Składnik Tau | Q9: Ostrzeżenie limit | R9: Ostrzeżenie toksyczność | S9: Psi stacji | T9: Tau stacji | U9: Uwagi
A10: 1 | B10: miejska | C10: =Powietrze_Dane!$B$12 | D10: =Powietrze_Dane!$C$12 | E10: =Powietrze_Dane!$D$12 | F10: =IF(C10&D10="","",IFERROR(INDEX(Powietrze_Mapowanie!$I$4:$I$40,MATCH(C10,Powietrze_Mapowanie!$G$4:$G$40,0)),IFERROR(INDEX(Powietrze_Mapowanie!$I$4:$I$40,MATCH(D10,Powietrze_Mapowanie!$G$4:$G$40,0)),IF(D10<>"",D10,C10)))) | G10: =IF(F10="","",IFERROR(INDEX(Powietrze_Mapowanie!$B$4:$B$20,MATCH(F10,Powietrze_Mapowanie!$A$4:$A$20,0)),"")) | H10: =IF(C10&D10="","",IFERROR(INDEX(Powietrze_Mapowanie!$J$4:$J$40,MATCH(C10,Powietrze_Mapowanie!$G$4:$G$40,0)),IFERROR(INDEX(Powietrze_Mapowanie!$J$4:$J$40,MATCH(D10,Powietrze_Mapowanie!$G$4:$G$40,0)),IF(D10<>"",D10,C10)))) | I10: =IF(H10="","",IFERROR(INDEX(Powietrze_Mapowanie!$E$4:$E$30,MATCH(H10,Powietrze_Mapowanie!$D$4:$D$30,0)),"")) | J10: =IF(COUNTA(B14:B23)=0,"",MIN(B14:B23)) | K10: =IF(COUNTA(B14:B23)=0,"",AVERAGE(B14:B23)) | L10: =IF(COUNTA(B14:B23)=0,"",MAX(B14:B23)) | M10: =IF(G10="","Brak limitu",IF(K10="","Brak danych",IF(K10>G10,"TAK","NIE"))) | N10: =IF(G10="","Brak limitu",IF(L10="","Brak danych",IF(L10>G10,"TAK","NIE"))) | O10: =IF(AND(ISNUMBER(K10),ISNUMBER(G10)),K10/G10,"") | P10: =IF(AND(ISNUMBER(K10),ISNUMBER(I10)),K10*I10,"") | Q10: =IF(AND(K10<>"",G10=""),"Brak wartości dopuszczalnej w instrukcji — zanieczyszczenie pominięto w indeksie jakości.","") | R10: =IF(AND(K10<>"",I10=""),"Brak współczynnika toksyczności w instrukcji — zanieczyszczenie pominięto w indeksie toksyczności.","") | S10: =SUMIF($B$10:$B$27,B10,$O$10:$O$27) | T10: =SUMIF($B$10:$B$27,B10,$P$10:$P$27) | U10: Wskaźnik liczony dla całej stacji
A11: 1 | B11: podmiejska | C11: =Powietrze_Dane!$B$12 | D11: =Powietrze_Dane!$C$12 | E11: =Powietrze_Dane!$D$12 | F11: =IF(C11&D11="","",IFERROR(INDEX(Powietrze_Mapowanie!$I$4:$I$40,MATCH(C11,Powietrze_Mapowanie!$G$4:$G$40,0)),IFERROR(INDEX(Powietrze_Mapowanie!$I$4:$I$40,MATCH(D11,Powietrze_Mapowanie!$G$4:$G$40,0)),IF(D11<>"",D11,C11)))) | G11: =IF(F11="","",IFERROR(INDEX(Powietrze_Mapowanie!$B$4:$B$20,MATCH(F11,Powietrze_Mapowanie!$A$4:$A$20,0)),"")) | H11: =IF(C11&D11="","",IFERROR(INDEX(Powietrze_Mapowanie!$J$4:$J$40,MATCH(C11,Powietrze_Mapowanie!$G$4:$G$40,0)),IFERROR(INDEX(Powietrze_Mapowanie!$J$4:$J$40,MATCH(D11,Powietrze_Mapowanie!$G$4:$G$40,0)),IF(D11<>"",D11,C11)))) | I11: =IF(H11="","",IFERROR(INDEX(Powietrze_Mapowanie!$E$4:$E$30,MATCH(H11,Powietrze_Mapowanie!$D$4:$D$30,0)),"")) | J11: =IF(COUNTA(C14:C23)=0,"",MIN(C14:C23)) | K11: =IF(COUNTA(C14:C23)=0,"",AVERAGE(C14:C23)) | L11: =IF(COUNTA(C14:C23)=0,"",MAX(C14:C23)) | M11: =IF(G11="","Brak limitu",IF(K11="","Brak danych",IF(K11>G11,"TAK","NIE"))) | N11: =IF(G11="","Brak limitu",IF(L11="","Brak danych",IF(L11>G11,"TAK","NIE"))) | O11: =IF(AND(ISNUMBER(K11),ISNUMBER(G11)),K11/G11,"") | P11: =IF(AND(ISNUMBER(K11),ISNUMBER(I11)),K11*I11,"") | Q11: =IF(AND(K11<>"",G11=""),"Brak wartości dopuszczalnej w instrukcji — zanieczyszczenie pominięto w indeksie jakości.","") | R11: =IF(AND(K11<>"",I11=""),"Brak współczynnika toksyczności w instrukcji — zanieczyszczenie pominięto w indeksie toksyczności.","") | S11: =SUMIF($B$10:$B$27,B11,$O$10:$O$27) | T11: =SUMIF($B$10:$B$27,B11,$P$10:$P$27) | U11: Wskaźnik liczony dla całej stacji
A12: 1 | B12: pozamiejska | C12: =Powietrze_Dane!$B$12 | D12: =Powietrze_Dane!$C$12 | E12: =Powietrze_Dane!$D$12 | F12: =IF(C12&D12="","",IFERROR(INDEX(Powietrze_Mapowanie!$I$4:$I$40,MATCH(C12,Powietrze_Mapowanie!$G$4:$G$40,0)),IFERROR(INDEX(Powietrze_Mapowanie!$I$4:$I$40,MATCH(D12,Powietrze_Mapowanie!$G$4:$G$40,0)),IF(D12<>"",D12,C12)))) | G12: =IF(F12="","",IFERROR(INDEX(Powietrze_Mapowanie!$B$4:$B$20,MATCH(F12,Powietrze_Mapowanie!$A$4:$A$20,0)),"")) | H12: =IF(C12&D12="","",IFERROR(INDEX(Powietrze_Mapowanie!$J$4:$J$40,MATCH(C12,Powietrze_Mapowanie!$G$4:$G$40,0)),IFERROR(INDEX(Powietrze_Mapowanie!$J$4:$J$40,MATCH(D12,Powietrze_Mapowanie!$G$4:$G$40,0)),IF(D12<>"",D12,C12)))) | I12: =IF(H12="","",IFERROR(INDEX(Powietrze_Mapowanie!$E$4:$E$30,MATCH(H12,Powietrze_Mapowanie!$D$4:$D$30,0)),"")) | J12: =IF(COUNTA(D14:D23)=0,"",MIN(D14:D23)) | K12: =IF(COUNTA(D14:D23)=0,"",AVERAGE(D14:D23)) | L12: =IF(COUNTA(D14:D23)=0,"",MAX(D14:D23)) | M12: =IF(G12="","Brak limitu",IF(K12="","Brak danych",IF(K12>G12,"TAK","NIE"))) | N12: =IF(G12="","Brak limitu",IF(L12="","Brak danych",IF(L12>G12,"TAK","NIE"))) | O12: =IF(AND(ISNUMBER(K12),ISNUMBER(G12)),K12/G12,"") | P12: =IF(AND(ISNUMBER(K12),ISNUMBER(I12)),K12*I12,"") | Q12: =IF(AND(K12<>"",G12=""),"Brak wartości dopuszczalnej w instrukcji — zanieczyszczenie pominięto w indeksie jakości.","") | R12: =IF(AND(K12<>"",I12=""),"Brak współczynnika toksyczności w instrukcji — zanieczyszczenie pominięto w indeksie toksyczności.","") | S12: =SUMIF($B$10:$B$27,B12,$O$10:$O$27) | T12: =SUMIF($B$10:$B$27,B12,$P$10:$P$27) | U12: Wskaźnik liczony dla całej stacji
A13: 2 | B13: miejska | C13: =Powietrze_Dane!$B$27 | D13: =Powietrze_Dane!$C$27 | E13: =Powietrze_Dane!$D$27 | F13: =IF(C13&D13="","",IFERROR(INDEX(Powietrze_Mapowanie!$I$4:$I$40,MATCH(C13,Powietrze_Mapowanie!$G$4:$G$40,0)),IFERROR(INDEX(Powietrze_Mapowanie!$I$4:$I$40,MATCH(D13,Powietrze_Mapowanie!$G$4:$G$40,0)),IF(D13<>"",D13,C13)))) | G13: =IF(F13="","",IFERROR(INDEX(Powietrze_Mapowanie!$B$4:$B$20,MATCH(F13,Powietrze_Mapowanie!$A$4:$A$20,0)),"")) | H13: =IF(C13&D13="","",IFERROR(INDEX(Powietrze_Mapowanie!$J$4:$J$40,MATCH(C13,Powietrze_Mapowanie!$G$4:$G$40,0)),IFERROR(INDEX(Powietrze_Mapowanie!$J$4:$J$40,MATCH(D13,Powietrze_Mapowanie!$G$4:$G$40,0)),IF(D13<>"",D13,C13)))) | I13: =IF(H13="","",IFERROR(INDEX(Powietrze_Mapowanie!$E$4:$E$30,MATCH(H13,Powietrze_Mapowanie!$D$4:$D$30,0)),"")) | J13: =IF(COUNTA(B29:B38)=0,"",MIN(B29:B38)) | K13: =IF(COUNTA(B29:B38)=0,"",AVERAGE(B29:B38)) | L13: =IF(COUNTA(B29:B38)=0,"",MAX(B29:B38)) | M13: =IF(G13="","Brak limitu",IF(K13="","Brak danych",IF(K13>G13,"TAK","NIE"))) | N13: =IF(G13="","Brak limitu",IF(L13="","Brak danych",IF(L13>G13,"TAK","NIE"))) | O13: =IF(AND(ISNUMBER(K13),ISNUMBER(G13)),K13/G13,"") | P13: =IF(AND(ISNUMBER(K13),ISNUMBER(I13)),K13*I13,"") | Q13: =IF(AND(K13<>"",G13=""),"Brak wartości dopuszczalnej w instrukcji — zanieczyszczenie pominięto w indeksie jakości.","") | R13: =IF(AND(K13<>"",I13=""),"Brak współczynnika toksyczności w instrukcji — zanieczyszczenie pominięto w indeksie toksyczności.","") | S13: =SUMIF($B$10:$B$27,B13,$O$10:$O$27) | T13: =SUMIF($B$10:$B$27,B13,$P$10:$P$27) | U13: Wskaźnik liczony dla całej stacji
A14: 2 | B14: podmiejska | C14: =Powietrze_Dane!$B$27 | D14: =Powietrze_Dane!$C$27 | E14: =Powietrze_Dane!$D$27 | F14: =IF(C14&D14="","",IFERROR(INDEX(Powietrze_Mapowanie!$I$4:$I$40,MATCH(C14,Powietrze_Mapowanie!$G$4:$G$40,0)),IFERROR(INDEX(Powietrze_Mapowanie!$I$4:$I$40,MATCH(D14,Powietrze_Mapowanie!$G$4:$G$40,0)),IF(D14<>"",D14,C14)))) | G14: =IF(F14="","",IFERROR(INDEX(Powietrze_Mapowanie!$B$4:$B$20,MATCH(F14,Powietrze_Mapowanie!$A$4:$A$20,0)),"")) | H14: =IF(C14&D14="","",IFERROR(INDEX(Powietrze_Mapowanie!$J$4:$J$40,MATCH(C14,Powietrze_Mapowanie!$G$4:$G$40,0)),IFERROR(INDEX(Powietrze_Mapowanie!$J$4:$J$40,MATCH(D14,Powietrze_Mapowanie!$G$4:$G$40,0)),IF(D14<>"",D14,C14)))) | I14: =IF(H14="","",IFERROR(INDEX(Powietrze_Mapowanie!$E$4:$E$30,MATCH(H14,Powietrze_Mapowanie!$D$4:$D$30,0)),"")) | J14: =IF(COUNTA(C29:C38)=0,"",MIN(C29:C38)) | K14: =IF(COUNTA(C29:C38)=0,"",AVERAGE(C29:C38)) | L14: =IF(COUNTA(C29:C38)=0,"",MAX(C29:C38)) | M14: =IF(G14="","Brak limitu",IF(K14="","Brak danych",IF(K14>G14,"TAK","NIE"))) | N14: =IF(G14="","Brak limitu",IF(L14="","Brak danych",IF(L14>G14,"TAK","NIE"))) | O14: =IF(AND(ISNUMBER(K14),ISNUMBER(G14)),K14/G14,"") | P14: =IF(AND(ISNUMBER(K14),ISNUMBER(I14)),K14*I14,"") | Q14: =IF(AND(K14<>"",G14=""),"Brak wartości dopuszczalnej w instrukcji — zanieczyszczenie pominięto w indeksie jakości.","") | R14: =IF(AND(K14<>"",I14=""),"Brak współczynnika toksyczności w instrukcji — zanieczyszczenie pominięto w indeksie toksyczności.","") | S14: =SUMIF($B$10:$B$27,B14,$O$10:$O$27) | T14: =SUMIF($B$10:$B$27,B14,$P$10:$P$27) | U14: Wskaźnik liczony dla całej stacji
A15: 2 | B15: pozamiejska | C15: =Powietrze_Dane!$B$27 | D15: =Powietrze_Dane!$C$27 | E15: =Powietrze_Dane!$D$27 | F15: =IF(C15&D15="","",IFERROR(INDEX(Powietrze_Mapowanie!$I$4:$I$40,MATCH(C15,Powietrze_Mapowanie!$G$4:$G$40,0)),IFERROR(INDEX(Powietrze_Mapowanie!$I$4:$I$40,MATCH(D15,Powietrze_Mapowanie!$G$4:$G$40,0)),IF(D15<>"",D15,C15)))) | G15: =IF(F15="","",IFERROR(INDEX(Powietrze_Mapowanie!$B$4:$B$20,MATCH(F15,Powietrze_Mapowanie!$A$4:$A$20,0)),"")) | H15: =IF(C15&D15="","",IFERROR(INDEX(Powietrze_Mapowanie!$J$4:$J$40,MATCH(C15,Powietrze_Mapowanie!$G$4:$G$40,0)),IFERROR(INDEX(Powietrze_Mapowanie!$J$4:$J$40,MATCH(D15,Powietrze_Mapowanie!$G$4:$G$40,0)),IF(D15<>"",D15,C15)))) | I15: =IF(H15="","",IFERROR(INDEX(Powietrze_Mapowanie!$E$4:$E$30,MATCH(H15,Powietrze_Mapowanie!$D$4:$D$30,0)),"")) | J15: =IF(COUNTA(D29:D38)=0,"",MIN(D29:D38)) | K15: =IF(COUNTA(D29:D38)=0,"",AVERAGE(D29:D38)) | L15: =IF(COUNTA(D29:D38)=0,"",MAX(D29:D38)) | M15: =IF(G15="","Brak limitu",IF(K15="","Brak danych",IF(K15>G15,"TAK","NIE"))) | N15: =IF(G15="","Brak limitu",IF(L15="","Brak danych",IF(L15>G15,"TAK","NIE"))) | O15: =IF(AND(ISNUMBER(K15),ISNUMBER(G15)),K15/G15,"") | P15: =IF(AND(ISNUMBER(K15),ISNUMBER(I15)),K15*I15,"") | Q15: =IF(AND(K15<>"",G15=""),"Brak wartości dopuszczalnej w instrukcji — zanieczyszczenie pominięto w indeksie jakości.","") | R15: =IF(AND(K15<>"",I15=""),"Brak współczynnika toksyczności w instrukcji — zanieczyszczenie pominięto w indeksie toksyczności.","") | S15: =SUMIF($B$10:$B$27,B15,$O$10:$O$27) | T15: =SUMIF($B$10:$B$27,B15,$P$10:$P$27) | U15: Wskaźnik liczony dla całej stacji
A16: 3 | B16: miejska | C16: =Powietrze_Dane!$B$42 | D16: =Powietrze_Dane!$C$42 | E16: =Powietrze_Dane!$D$42 | F16: =IF(C16&D16="","",IFERROR(INDEX(Powietrze_Mapowanie!$I$4:$I$40,MATCH(C16,Powietrze_Mapowanie!$G$4:$G$40,0)),IFERROR(INDEX(Powietrze_Mapowanie!$I$4:$I$40,MATCH(D16,Powietrze_Mapowanie!$G$4:$G$40,0)),IF(D16<>"",D16,C16)))) | G16: =IF(F16="","",IFERROR(INDEX(Powietrze_Mapowanie!$B$4:$B$20,MATCH(F16,Powietrze_Mapowanie!$A$4:$A$20,0)),"")) | H16: =IF(C16&D16="","",IFERROR(INDEX(Powietrze_Mapowanie!$J$4:$J$40,MATCH(C16,Powietrze_Mapowanie!$G$4:$G$40,0)),IFERROR(INDEX(Powietrze_Mapowanie!$J$4:$J$40,MATCH(D16,Powietrze_Mapowanie!$G$4:$G$40,0)),IF(D16<>"",D16,C16)))) | I16: =IF(H16="","",IFERROR(INDEX(Powietrze_Mapowanie!$E$4:$E$30,MATCH(H16,Powietrze_Mapowanie!$D$4:$D$30,0)),"")) | J16: =IF(COUNTA(B44:B53)=0,"",MIN(B44:B53)) | K16: =IF(COUNTA(B44:B53)=0,"",AVERAGE(B44:B53)) | L16: =IF(COUNTA(B44:B53)=0,"",MAX(B44:B53)) | M16: =IF(G16="","Brak limitu",IF(K16="","Brak danych",IF(K16>G16,"TAK","NIE"))) | N16: =IF(G16="","Brak limitu",IF(L16="","Brak danych",IF(L16>G16,"TAK","NIE"))) | O16: =IF(AND(ISNUMBER(K16),ISNUMBER(G16)),K16/G16,"") | P16: =IF(AND(ISNUMBER(K16),ISNUMBER(I16)),K16*I16,"") | Q16: =IF(AND(K16<>"",G16=""),"Brak wartości dopuszczalnej w instrukcji — zanieczyszczenie pominięto w indeksie jakości.","") | R16: =IF(AND(K16<>"",I16=""),"Brak współczynnika toksyczności w instrukcji — zanieczyszczenie pominięto w indeksie toksyczności.","") | S16: =SUMIF($B$10:$B$27,B16,$O$10:$O$27) | T16: =SUMIF($B$10:$B$27,B16,$P$10:$P$27) | U16: Wskaźnik liczony dla całej stacji
A17: 3 | B17: podmiejska | C17: =Powietrze_Dane!$B$42 | D17: =Powietrze_Dane!$C$42 | E17: =Powietrze_Dane!$D$42 | F17: =IF(C17&D17="","",IFERROR(INDEX(Powietrze_Mapowanie!$I$4:$I$40,MATCH(C17,Powietrze_Mapowanie!$G$4:$G$40,0)),IFERROR(INDEX(Powietrze_Mapowanie!$I$4:$I$40,MATCH(D17,Powietrze_Mapowanie!$G$4:$G$40,0)),IF(D17<>"",D17,C17)))) | G17: =IF(F17="","",IFERROR(INDEX(Powietrze_Mapowanie!$B$4:$B$20,MATCH(F17,Powietrze_Mapowanie!$A$4:$A$20,0)),"")) | H17: =IF(C17&D17="","",IFERROR(INDEX(Powietrze_Mapowanie!$J$4:$J$40,MATCH(C17,Powietrze_Mapowanie!$G$4:$G$40,0)),IFERROR(INDEX(Powietrze_Mapowanie!$J$4:$J$40,MATCH(D17,Powietrze_Mapowanie!$G$4:$G$40,0)),IF(D17<>"",D17,C17)))) | I17: =IF(H17="","",IFERROR(INDEX(Powietrze_Mapowanie!$E$4:$E$30,MATCH(H17,Powietrze_Mapowanie!$D$4:$D$30,0)),"")) | J17: =IF(COUNTA(C44:C53)=0,"",MIN(C44:C53)) | K17: =IF(COUNTA(C44:C53)=0,"",AVERAGE(C44:C53)) | L17: =IF(COUNTA(C44:C53)=0,"",MAX(C44:C53)) | M17: =IF(G17="","Brak limitu",IF(K17="","Brak danych",IF(K17>G17,"TAK","NIE"))) | N17: =IF(G17="","Brak limitu",IF(L17="","Brak danych",IF(L17>G17,"TAK","NIE"))) | O17: =IF(AND(ISNUMBER(K17),ISNUMBER(G17)),K17/G17,"") | P17: =IF(AND(ISNUMBER(K17),ISNUMBER(I17)),K17*I17,"") | Q17: =IF(AND(K17<>"",G17=""),"Brak wartości dopuszczalnej w instrukcji — zanieczyszczenie pominięto w indeksie jakości.","") | R17: =IF(AND(K17<>"",I17=""),"Brak współczynnika toksyczności w instrukcji — zanieczyszczenie pominięto w indeksie toksyczności.","") | S17: =SUMIF($B$10:$B$27,B17,$O$10:$O$27) | T17: =SUMIF($B$10:$B$27,B17,$P$10:$P$27) | U17: Wskaźnik liczony dla całej stacji
A18: 3 | B18: pozamiejska | C18: =Powietrze_Dane!$B$42 | D18: =Powietrze_Dane!$C$42 | E18: =Powietrze_Dane!$D$42 | F18: =IF(C18&D18="","",IFERROR(INDEX(Powietrze_Mapowanie!$I$4:$I$40,MATCH(C18,Powietrze_Mapowanie!$G$4:$G$40,0)),IFERROR(INDEX(Powietrze_Mapowanie!$I$4:$I$40,MATCH(D18,Powietrze_Mapowanie!$G$4:$G$40,0)),IF(D18<>"",D18,C18)))) | G18: =IF(F18="","",IFERROR(INDEX(Powietrze_Mapowanie!$B$4:$B$20,MATCH(F18,Powietrze_Mapowanie!$A$4:$A$20,0)),"")) | H18: =IF(C18&D18="","",IFERROR(INDEX(Powietrze_Mapowanie!$J$4:$J$40,MATCH(C18,Powietrze_Mapowanie!$G$4:$G$40,0)),IFERROR(INDEX(Powietrze_Mapowanie!$J$4:$J$40,MATCH(D18,Powietrze_Mapowanie!$G$4:$G$40,0)),IF(D18<>"",D18,C18)))) | I18: =IF(H18="","",IFERROR(INDEX(Powietrze_Mapowanie!$E$4:$E$30,MATCH(H18,Powietrze_Mapowanie!$D$4:$D$30,0)),"")) | J18: =IF(COUNTA(D44:D53)=0,"",MIN(D44:D53)) | K18: =IF(COUNTA(D44:D53)=0,"",AVERAGE(D44:D53)) | L18: =IF(COUNTA(D44:D53)=0,"",MAX(D44:D53)) | M18: =IF(G18="","Brak limitu",IF(K18="","Brak danych",IF(K18>G18,"TAK","NIE"))) | N18: =IF(G18="","Brak limitu",IF(L18="","Brak danych",IF(L18>G18,"TAK","NIE"))) | O18: =IF(AND(ISNUMBER(K18),ISNUMBER(G18)),K18/G18,"") | P18: =IF(AND(ISNUMBER(K18),ISNUMBER(I18)),K18*I18,"") | Q18: =IF(AND(K18<>"",G18=""),"Brak wartości dopuszczalnej w instrukcji — zanieczyszczenie pominięto w indeksie jakości.","") | R18: =IF(AND(K18<>"",I18=""),"Brak współczynnika toksyczności w instrukcji — zanieczyszczenie pominięto w indeksie toksyczności.","") | S18: =SUMIF($B$10:$B$27,B18,$O$10:$O$27) | T18: =SUMIF($B$10:$B$27,B18,$P$10:$P$27) | U18: Wskaźnik liczony dla całej stacji
A19: 4 | B19: miejska | C19: =Powietrze_Dane!$B$57 | D19: =Powietrze_Dane!$C$57 | E19: =Powietrze_Dane!$D$57 | F19: =IF(C19&D19="","",IFERROR(INDEX(Powietrze_Mapowanie!$I$4:$I$40,MATCH(C19,Powietrze_Mapowanie!$G$4:$G$40,0)),IFERROR(INDEX(Powietrze_Mapowanie!$I$4:$I$40,MATCH(D19,Powietrze_Mapowanie!$G$4:$G$40,0)),IF(D19<>"",D19,C19)))) | G19: =IF(F19="","",IFERROR(INDEX(Powietrze_Mapowanie!$B$4:$B$20,MATCH(F19,Powietrze_Mapowanie!$A$4:$A$20,0)),"")) | H19: =IF(C19&D19="","",IFERROR(INDEX(Powietrze_Mapowanie!$J$4:$J$40,MATCH(C19,Powietrze_Mapowanie!$G$4:$G$40,0)),IFERROR(INDEX(Powietrze_Mapowanie!$J$4:$J$40,MATCH(D19,Powietrze_Mapowanie!$G$4:$G$40,0)),IF(D19<>"",D19,C19)))) | I19: =IF(H19="","",IFERROR(INDEX(Powietrze_Mapowanie!$E$4:$E$30,MATCH(H19,Powietrze_Mapowanie!$D$4:$D$30,0)),"")) | J19: =IF(COUNTA(B59:B68)=0,"",MIN(B59:B68)) | K19: =IF(COUNTA(B59:B68)=0,"",AVERAGE(B59:B68)) | L19: =IF(COUNTA(B59:B68)=0,"",MAX(B59:B68)) | M19: =IF(G19="","Brak limitu",IF(K19="","Brak danych",IF(K19>G19,"TAK","NIE"))) | N19: =IF(G19="","Brak limitu",IF(L19="","Brak danych",IF(L19>G19,"TAK","NIE"))) | O19: =IF(AND(ISNUMBER(K19),ISNUMBER(G19)),K19/G19,"") | P19: =IF(AND(ISNUMBER(K19),ISNUMBER(I19)),K19*I19,"") | Q19: =IF(AND(K19<>"",G19=""),"Brak wartości dopuszczalnej w instrukcji — zanieczyszczenie pominięto w indeksie jakości.","") | R19: =IF(AND(K19<>"",I19=""),"Brak współczynnika toksyczności w instrukcji — zanieczyszczenie pominięto w indeksie toksyczności.","") | S19: =SUMIF($B$10:$B$27,B19,$O$10:$O$27) | T19: =SUMIF($B$10:$B$27,B19,$P$10:$P$27) | U19: Wskaźnik liczony dla całej stacji
A20: 4 | B20: podmiejska | C20: =Powietrze_Dane!$B$57 | D20: =Powietrze_Dane!$C$57 | E20: =Powietrze_Dane!$D$57 | F20: =IF(C20&D20="","",IFERROR(INDEX(Powietrze_Mapowanie!$I$4:$I$40,MATCH(C20,Powietrze_Mapowanie!$G$4:$G$40,0)),IFERROR(INDEX(Powietrze_Mapowanie!$I$4:$I$40,MATCH(D20,Powietrze_Mapowanie!$G$4:$G$40,0)),IF(D20<>"",D20,C20)))) | G20: =IF(F20="","",IFERROR(INDEX(Powietrze_Mapowanie!$B$4:$B$20,MATCH(F20,Powietrze_Mapowanie!$A$4:$A$20,0)),"")) | H20: =IF(C20&D20="","",IFERROR(INDEX(Powietrze_Mapowanie!$J$4:$J$40,MATCH(C20,Powietrze_Mapowanie!$G$4:$G$40,0)),IFERROR(INDEX(Powietrze_Mapowanie!$J$4:$J$40,MATCH(D20,Powietrze_Mapowanie!$G$4:$G$40,0)),IF(D20<>"",D20,C20)))) | I20: =IF(H20="","",IFERROR(INDEX(Powietrze_Mapowanie!$E$4:$E$30,MATCH(H20,Powietrze_Mapowanie!$D$4:$D$30,0)),"")) | J20: =IF(COUNTA(C59:C68)=0,"",MIN(C59:C68)) | K20: =IF(COUNTA(C59:C68)=0,"",AVERAGE(C59:C68)) | L20: =IF(COUNTA(C59:C68)=0,"",MAX(C59:C68)) | M20: =IF(G20="","Brak limitu",IF(K20="","Brak danych",IF(K20>G20,"TAK","NIE"))) | N20: =IF(G20="","Brak limitu",IF(L20="","Brak danych",IF(L20>G20,"TAK","NIE"))) | O20: =IF(AND(ISNUMBER(K20),ISNUMBER(G20)),K20/G20,"") | P20: =IF(AND(ISNUMBER(K20),ISNUMBER(I20)),K20*I20,"") | Q20: =IF(AND(K20<>"",G20=""),"Brak wartości dopuszczalnej w instrukcji — zanieczyszczenie pominięto w indeksie jakości.","") | R20: =IF(AND(K20<>"",I20=""),"Brak współczynnika toksyczności w instrukcji — zanieczyszczenie pominięto w indeksie toksyczności.","") | S20: =SUMIF($B$10:$B$27,B20,$O$10:$O$27) | T20: =SUMIF($B$10:$B$27,B20,$P$10:$P$27) | U20: Wskaźnik liczony dla całej stacji
A21: 4 | B21: pozamiejska | C21: =Powietrze_Dane!$B$57 | D21: =Powietrze_Dane!$C$57 | E21: =Powietrze_Dane!$D$57 | F21: =IF(C21&D21="","",IFERROR(INDEX(Powietrze_Mapowanie!$I$4:$I$40,MATCH(C21,Powietrze_Mapowanie!$G$4:$G$40,0)),IFERROR(INDEX(Powietrze_Mapowanie!$I$4:$I$40,MATCH(D21,Powietrze_Mapowanie!$G$4:$G$40,0)),IF(D21<>"",D21,C21)))) | G21: =IF(F21="","",IFERROR(INDEX(Powietrze_Mapowanie!$B$4:$B$20,MATCH(F21,Powietrze_Mapowanie!$A$4:$A$20,0)),"")) | H21: =IF(C21&D21="","",IFERROR(INDEX(Powietrze_Mapowanie!$J$4:$J$40,MATCH(C21,Powietrze_Mapowanie!$G$4:$G$40,0)),IFERROR(INDEX(Powietrze_Mapowanie!$J$4:$J$40,MATCH(D21,Powietrze_Mapowanie!$G$4:$G$40,0)),IF(D21<>"",D21,C21)))) | I21: =IF(H21="","",IFERROR(INDEX(Powietrze_Mapowanie!$E$4:$E$30,MATCH(H21,Powietrze_Mapowanie!$D$4:$D$30,0)),"")) | J21: =IF(COUNTA(D59:D68)=0,"",MIN(D59:D68)) | K21: =IF(COUNTA(D59:D68)=0,"",AVERAGE(D59:D68)) | L21: =IF(COUNTA(D59:D68)=0,"",MAX(D59:D68)) | M21: =IF(G21="","Brak limitu",IF(K21="","Brak danych",IF(K21>G21,"TAK","NIE"))) | N21: =IF(G21="","Brak limitu",IF(L21="","Brak danych",IF(L21>G21,"TAK","NIE"))) | O21: =IF(AND(ISNUMBER(K21),ISNUMBER(G21)),K21/G21,"") | P21: =IF(AND(ISNUMBER(K21),ISNUMBER(I21)),K21*I21,"") | Q21: =IF(AND(K21<>"",G21=""),"Brak wartości dopuszczalnej w instrukcji — zanieczyszczenie pominięto w indeksie jakości.","") | R21: =IF(AND(K21<>"",I21=""),"Brak współczynnika toksyczności w instrukcji — zanieczyszczenie pominięto w indeksie toksyczności.","") | S21: =SUMIF($B$10:$B$27,B21,$O$10:$O$27) | T21: =SUMIF($B$10:$B$27,B21,$P$10:$P$27) | U21: Wskaźnik liczony dla całej stacji
A22: 5 | B22: miejska | C22: =Powietrze_Dane!$B$72 | D22: =Powietrze_Dane!$C$72 | E22: =Powietrze_Dane!$D$72 | F22: =IF(C22&D22="","",IFERROR(INDEX(Powietrze_Mapowanie!$I$4:$I$40,MATCH(C22,Powietrze_Mapowanie!$G$4:$G$40,0)),IFERROR(INDEX(Powietrze_Mapowanie!$I$4:$I$40,MATCH(D22,Powietrze_Mapowanie!$G$4:$G$40,0)),IF(D22<>"",D22,C22)))) | G22: =IF(F22="","",IFERROR(INDEX(Powietrze_Mapowanie!$B$4:$B$20,MATCH(F22,Powietrze_Mapowanie!$A$4:$A$20,0)),"")) | H22: =IF(C22&D22="","",IFERROR(INDEX(Powietrze_Mapowanie!$J$4:$J$40,MATCH(C22,Powietrze_Mapowanie!$G$4:$G$40,0)),IFERROR(INDEX(Powietrze_Mapowanie!$J$4:$J$40,MATCH(D22,Powietrze_Mapowanie!$G$4:$G$40,0)),IF(D22<>"",D22,C22)))) | I22: =IF(H22="","",IFERROR(INDEX(Powietrze_Mapowanie!$E$4:$E$30,MATCH(H22,Powietrze_Mapowanie!$D$4:$D$30,0)),"")) | J22: =IF(COUNTA(B74:B83)=0,"",MIN(B74:B83)) | K22: =IF(COUNTA(B74:B83)=0,"",AVERAGE(B74:B83)) | L22: =IF(COUNTA(B74:B83)=0,"",MAX(B74:B83)) | M22: =IF(G22="","Brak limitu",IF(K22="","Brak danych",IF(K22>G22,"TAK","NIE"))) | N22: =IF(G22="","Brak limitu",IF(L22="","Brak danych",IF(L22>G22,"TAK","NIE"))) | O22: =IF(AND(ISNUMBER(K22),ISNUMBER(G22)),K22/G22,"") | P22: =IF(AND(ISNUMBER(K22),ISNUMBER(I22)),K22*I22,"") | Q22: =IF(AND(K22<>"",G22=""),"Brak wartości dopuszczalnej w instrukcji — zanieczyszczenie pominięto w indeksie jakości.","") | R22: =IF(AND(K22<>"",I22=""),"Brak współczynnika toksyczności w instrukcji — zanieczyszczenie pominięto w indeksie toksyczności.","") | S22: =SUMIF($B$10:$B$27,B22,$O$10:$O$27) | T22: =SUMIF($B$10:$B$27,B22,$P$10:$P$27) | U22: Wskaźnik liczony dla całej stacji
A23: 5 | B23: podmiejska | C23: =Powietrze_Dane!$B$72 | D23: =Powietrze_Dane!$C$72 | E23: =Powietrze_Dane!$D$72 | F23: =IF(C23&D23="","",IFERROR(INDEX(Powietrze_Mapowanie!$I$4:$I$40,MATCH(C23,Powietrze_Mapowanie!$G$4:$G$40,0)),IFERROR(INDEX(Powietrze_Mapowanie!$I$4:$I$40,MATCH(D23,Powietrze_Mapowanie!$G$4:$G$40,0)),IF(D23<>"",D23,C23)))) | G23: =IF(F23="","",IFERROR(INDEX(Powietrze_Mapowanie!$B$4:$B$20,MATCH(F23,Powietrze_Mapowanie!$A$4:$A$20,0)),"")) | H23: =IF(C23&D23="","",IFERROR(INDEX(Powietrze_Mapowanie!$J$4:$J$40,MATCH(C23,Powietrze_Mapowanie!$G$4:$G$40,0)),IFERROR(INDEX(Powietrze_Mapowanie!$J$4:$J$40,MATCH(D23,Powietrze_Mapowanie!$G$4:$G$40,0)),IF(D23<>"",D23,C23)))) | I23: =IF(H23="","",IFERROR(INDEX(Powietrze_Mapowanie!$E$4:$E$30,MATCH(H23,Powietrze_Mapowanie!$D$4:$D$30,0)),"")) | J23: =IF(COUNTA(C74:C83)=0,"",MIN(C74:C83)) | K23: =IF(COUNTA(C74:C83)=0,"",AVERAGE(C74:C83)) | L23: =IF(COUNTA(C74:C83)=0,"",MAX(C74:C83)) | M23: =IF(G23="","Brak limitu",IF(K23="","Brak danych",IF(K23>G23,"TAK","NIE"))) | N23: =IF(G23="","Brak limitu",IF(L23="","Brak danych",IF(L23>G23,"TAK","NIE"))) | O23: =IF(AND(ISNUMBER(K23),ISNUMBER(G23)),K23/G23,"") | P23: =IF(AND(ISNUMBER(K23),ISNUMBER(I23)),K23*I23,"") | Q23: =IF(AND(K23<>"",G23=""),"Brak wartości dopuszczalnej w instrukcji — zanieczyszczenie pominięto w indeksie jakości.","") | R23: =IF(AND(K23<>"",I23=""),"Brak współczynnika toksyczności w instrukcji — zanieczyszczenie pominięto w indeksie toksyczności.","") | S23: =SUMIF($B$10:$B$27,B23,$O$10:$O$27) | T23: =SUMIF($B$10:$B$27,B23,$P$10:$P$27) | U23: Wskaźnik liczony dla całej stacji
A24: 5 | B24: pozamiejska | C24: =Powietrze_Dane!$B$72 | D24: =Powietrze_Dane!$C$72 | E24: =Powietrze_Dane!$D$72 | F24: =IF(C24&D24="","",IFERROR(INDEX(Powietrze_Mapowanie!$I$4:$I$40,MATCH(C24,Powietrze_Mapowanie!$G$4:$G$40,0)),IFERROR(INDEX(Powietrze_Mapowanie!$I$4:$I$40,MATCH(D24,Powietrze_Mapowanie!$G$4:$G$40,0)),IF(D24<>"",D24,C24)))) | G24: =IF(F24="","",IFERROR(INDEX(Powietrze_Mapowanie!$B$4:$B$20,MATCH(F24,Powietrze_Mapowanie!$A$4:$A$20,0)),"")) | H24: =IF(C24&D24="","",IFERROR(INDEX(Powietrze_Mapowanie!$J$4:$J$40,MATCH(C24,Powietrze_Mapowanie!$G$4:$G$40,0)),IFERROR(INDEX(Powietrze_Mapowanie!$J$4:$J$40,MATCH(D24,Powietrze_Mapowanie!$G$4:$G$40,0)),IF(D24<>"",D24,C24)))) | I24: =IF(H24="","",IFERROR(INDEX(Powietrze_Mapowanie!$E$4:$E$30,MATCH(H24,Powietrze_Mapowanie!$D$4:$D$30,0)),"")) | J24: =IF(COUNTA(D74:D83)=0,"",MIN(D74:D83)) | K24: =IF(COUNTA(D74:D83)=0,"",AVERAGE(D74:D83)) | L24: =IF(COUNTA(D74:D83)=0,"",MAX(D74:D83)) | M24: =IF(G24="","Brak limitu",IF(K24="","Brak danych",IF(K24>G24,"TAK","NIE"))) | N24: =IF(G24="","Brak limitu",IF(L24="","Brak danych",IF(L24>G24,"TAK","NIE"))) | O24: =IF(AND(ISNUMBER(K24),ISNUMBER(G24)),K24/G24,"") | P24: =IF(AND(ISNUMBER(K24),ISNUMBER(I24)),K24*I24,"") | Q24: =IF(AND(K24<>"",G24=""),"Brak wartości dopuszczalnej w instrukcji — zanieczyszczenie pominięto w indeksie jakości.","") | R24: =IF(AND(K24<>"",I24=""),"Brak współczynnika toksyczności w instrukcji — zanieczyszczenie pominięto w indeksie toksyczności.","") | S24: =SUMIF($B$10:$B$27,B24,$O$10:$O$27) | T24: =SUMIF($B$10:$B$27,B24,$P$10:$P$27) | U24: Wskaźnik liczony dla całej stacji
A25: 6 | B25: miejska | C25: =Powietrze_Dane!$B$87 | D25: =Powietrze_Dane!$C$87 | E25: =Powietrze_Dane!$D$87 | F25: =IF(C25&D25="","",IFERROR(INDEX(Powietrze_Mapowanie!$I$4:$I$40,MATCH(C25,Powietrze_Mapowanie!$G$4:$G$40,0)),IFERROR(INDEX(Powietrze_Mapowanie!$I$4:$I$40,MATCH(D25,Powietrze_Mapowanie!$G$4:$G$40,0)),IF(D25<>"",D25,C25)))) | G25: =IF(F25="","",IFERROR(INDEX(Powietrze_Mapowanie!$B$4:$B$20,MATCH(F25,Powietrze_Mapowanie!$A$4:$A$20,0)),"")) | H25: =IF(C25&D25="","",IFERROR(INDEX(Powietrze_Mapowanie!$J$4:$J$40,MATCH(C25,Powietrze_Mapowanie!$G$4:$G$40,0)),IFERROR(INDEX(Powietrze_Mapowanie!$J$4:$J$40,MATCH(D25,Powietrze_Mapowanie!$G$4:$G$40,0)),IF(D25<>"",D25,C25)))) | I25: =IF(H25="","",IFERROR(INDEX(Powietrze_Mapowanie!$E$4:$E$30,MATCH(H25,Powietrze_Mapowanie!$D$4:$D$30,0)),"")) | J25: =IF(COUNTA(B89:B98)=0,"",MIN(B89:B98)) | K25: =IF(COUNTA(B89:B98)=0,"",AVERAGE(B89:B98)) | L25: =IF(COUNTA(B89:B98)=0,"",MAX(B89:B98)) | M25: =IF(G25="","Brak limitu",IF(K25="","Brak danych",IF(K25>G25,"TAK","NIE"))) | N25: =IF(G25="","Brak limitu",IF(L25="","Brak danych",IF(L25>G25,"TAK","NIE"))) | O25: =IF(AND(ISNUMBER(K25),ISNUMBER(G25)),K25/G25,"") | P25: =IF(AND(ISNUMBER(K25),ISNUMBER(I25)),K25*I25,"") | Q25: =IF(AND(K25<>"",G25=""),"Brak wartości dopuszczalnej w instrukcji — zanieczyszczenie pominięto w indeksie jakości.","") | R25: =IF(AND(K25<>"",I25=""),"Brak współczynnika toksyczności w instrukcji — zanieczyszczenie pominięto w indeksie toksyczności.","") | S25: =SUMIF($B$10:$B$27,B25,$O$10:$O$27) | T25: =SUMIF($B$10:$B$27,B25,$P$10:$P$27) | U25: Wskaźnik liczony dla całej stacji
A26: 6 | B26: podmiejska | C26: =Powietrze_Dane!$B$87 | D26: =Powietrze_Dane!$C$87 | E26: =Powietrze_Dane!$D$87 | F26: =IF(C26&D26="","",IFERROR(INDEX(Powietrze_Mapowanie!$I$4:$I$40,MATCH(C26,Powietrze_Mapowanie!$G$4:$G$40,0)),IFERROR(INDEX(Powietrze_Mapowanie!$I$4:$I$40,MATCH(D26,Powietrze_Mapowanie!$G$4:$G$40,0)),IF(D26<>"",D26,C26)))) | G26: =IF(F26="","",IFERROR(INDEX(Powietrze_Mapowanie!$B$4:$B$20,MATCH(F26,Powietrze_Mapowanie!$A$4:$A$20,0)),"")) | H26: =IF(C26&D26="","",IFERROR(INDEX(Powietrze_Mapowanie!$J$4:$J$40,MATCH(C26,Powietrze_Mapowanie!$G$4:$G$40,0)),IFERROR(INDEX(Powietrze_Mapowanie!$J$4:$J$40,MATCH(D26,Powietrze_Mapowanie!$G$4:$G$40,0)),IF(D26<>"",D26,C26)))) | I26: =IF(H26="","",IFERROR(INDEX(Powietrze_Mapowanie!$E$4:$E$30,MATCH(H26,Powietrze_Mapowanie!$D$4:$D$30,0)),"")) | J26: =IF(COUNTA(C89:C98)=0,"",MIN(C89:C98)) | K26: =IF(COUNTA(C89:C98)=0,"",AVERAGE(C89:C98)) | L26: =IF(COUNTA(C89:C98)=0,"",MAX(C89:C98)) | M26: =IF(G26="","Brak limitu",IF(K26="","Brak danych",IF(K26>G26,"TAK","NIE"))) | N26: =IF(G26="","Brak limitu",IF(L26="","Brak danych",IF(L26>G26,"TAK","NIE"))) | O26: =IF(AND(ISNUMBER(K26),ISNUMBER(G26)),K26/G26,"") | P26: =IF(AND(ISNUMBER(K26),ISNUMBER(I26)),K26*I26,"") | Q26: =IF(AND(K26<>"",G26=""),"Brak wartości dopuszczalnej w instrukcji — zanieczyszczenie pominięto w indeksie jakości.","") | R26: =IF(AND(K26<>"",I26=""),"Brak współczynnika toksyczności w instrukcji — zanieczyszczenie pominięto w indeksie toksyczności.","") | S26: =SUMIF($B$10:$B$27,B26,$O$10:$O$27) | T26: =SUMIF($B$10:$B$27,B26,$P$10:$P$27) | U26: Wskaźnik liczony dla całej stacji
A27: 6 | B27: pozamiejska | C27: =Powietrze_Dane!$B$87 | D27: =Powietrze_Dane!$C$87 | E27: =Powietrze_Dane!$D$87 | F27: =IF(C27&D27="","",IFERROR(INDEX(Powietrze_Mapowanie!$I$4:$I$40,MATCH(C27,Powietrze_Mapowanie!$G$4:$G$40,0)),IFERROR(INDEX(Powietrze_Mapowanie!$I$4:$I$40,MATCH(D27,Powietrze_Mapowanie!$G$4:$G$40,0)),IF(D27<>"",D27,C27)))) | G27: =IF(F27="","",IFERROR(INDEX(Powietrze_Mapowanie!$B$4:$B$20,MATCH(F27,Powietrze_Mapowanie!$A$4:$A$20,0)),"")) | H27: =IF(C27&D27="","",IFERROR(INDEX(Powietrze_Mapowanie!$J$4:$J$40,MATCH(C27,Powietrze_Mapowanie!$G$4:$G$40,0)),IFERROR(INDEX(Powietrze_Mapowanie!$J$4:$J$40,MATCH(D27,Powietrze_Mapowanie!$G$4:$G$40,0)),IF(D27<>"",D27,C27)))) | I27: =IF(H27="","",IFERROR(INDEX(Powietrze_Mapowanie!$E$4:$E$30,MATCH(H27,Powietrze_Mapowanie!$D$4:$D$30,0)),"")) | J27: =IF(COUNTA(D89:D98)=0,"",MIN(D89:D98)) | K27: =IF(COUNTA(D89:D98)=0,"",AVERAGE(D89:D98)) | L27: =IF(COUNTA(D89:D98)=0,"",MAX(D89:D98)) | M27: =IF(G27="","Brak limitu",IF(K27="","Brak danych",IF(K27>G27,"TAK","NIE"))) | N27: =IF(G27="","Brak limitu",IF(L27="","Brak danych",IF(L27>G27,"TAK","NIE"))) | O27: =IF(AND(ISNUMBER(K27),ISNUMBER(G27)),K27/G27,"") | P27: =IF(AND(ISNUMBER(K27),ISNUMBER(I27)),K27*I27,"") | Q27: =IF(AND(K27<>"",G27=""),"Brak wartości dopuszczalnej w instrukcji — zanieczyszczenie pominięto w indeksie jakości.","") | R27: =IF(AND(K27<>"",I27=""),"Brak współczynnika toksyczności w instrukcji — zanieczyszczenie pominięto w indeksie toksyczności.","") | S27: =SUMIF($B$10:$B$27,B27,$O$10:$O$27) | T27: =SUMIF($B$10:$B$27,B27,$P$10:$P$27) | U27: Wskaźnik liczony dla całej stacji

Sheet Powietrze_Wykresy
A1: Powietrze - wykresy
A2: Wykresy korzystają bezpośrednio z danych z arkusza Powietrze_Dane.

Sheet Gleba_Dane
A1: Gleba - dane wejściowe
A3: Kwasowość czynna
A4: Przedmiot analizy | B4: Pomiar 1 | C4: Pomiar 2 | D4: Średnia
A5: Woda destylowana | B5: 6.7 | C5: 6.8 | D5: =IF(COUNTA(B5:C5)=0,"",AVERAGE(B5:C5))
A6: Badana próbka gleby | B6: 5.6 | C6: 5.5 | D6: =IF(COUNTA(B6:C6)=0,"",AVERAGE(B6:C6))
A9: Kwasowość wymienna
A10: Przedmiot analizy | B10: Pomiar 1 | C10: Pomiar 2 | D10: Średnia
A11: KCl | B11: 6.9 | C11: 7 | D11: =IF(COUNTA(B11:C11)=0,"",AVERAGE(B11:C11))
A12: Badana próbka gleby | B12: 4.8 | C12: 4.9 | D12: =IF(COUNTA(B12:C12)=0,"",AVERAGE(B12:C12))
A15: Kwasowość hydrolityczna
A16: Parametr | B16: Wartość | C16: Jednostka
A17: VNaOH | B17: 4.2 | C17: cm3
A18: c_NaOH | B18: 0.1 | C18: mol/dm3
A19: k | B19: 1.75 | C19: współczynnik
A22: Suma kationów zasadowych
A23: Parametr | B23: Wartość | C23: Jednostka
A24: V_HCl | B24: 25 | C24: cm3
A25: c_HCl | B25: 0.1 | C25: mol/dm3
A26: V1_NaOH | B26: 7.5 | C26: cm3
A27: c1_NaOH | B27: 0.1 | C27: mol/dm3
A30: Parametry dla 1 ha
A31: Parametr | B31: Wartość | C31: Jednostka
A32: p | B32: 10000 | C32: m2
A33: h | B33: 0.2 | C33: m
A34: rho | B34: 1500 | C34: kg/m3

Sheet Gleba_Wyniki
A1: Gleba - wyniki
A3: Wynik | B3: Wartość | C3: Jednostka | D3: Uwagi
A4: Średnie pH wody destylowanej | B4: =IF(COUNTA(Gleba_Dane!B5:C5)=0,"",AVERAGE(Gleba_Dane!B5:C5)) | D4: wartość pomocnicza | E4: Interpretacja
A5: Średnie pH próbki w wodzie | B5: =IF(COUNTA(Gleba_Dane!B6:C6)=0,"",AVERAGE(Gleba_Dane!B6:C6)) | D5: kwasowość czynna | E5: określ kategorię gleby
A6: Średnie pH KCl | B6: =IF(COUNTA(Gleba_Dane!B11:C11)=0,"",AVERAGE(Gleba_Dane!B11:C11)) | D6: wartość pomocnicza | E6: odnieś pH KCl do klasy gleby uprawnej i leśnej
A7: Średnie pH próbki w KCl | B7: =IF(COUNTA(Gleba_Dane!B12:C12)=0,"",AVERAGE(Gleba_Dane!B12:C12)) | D7: podstawa klasyfikacji | E7: skomentuj Hh, S i T
A8: Hh | B8: =IF(OR(Gleba_Dane!B17="",Gleba_Dane!B18="",Gleba_Dane!B19=""),"",Gleba_Dane!B17*Gleba_Dane!B18*10*Gleba_Dane!B19) | C8: mmol(+)/100 g | D8: kwasowość hydrolityczna
A9: Mz | B9: =IF(OR(Gleba_Dane!B32="",Gleba_Dane!B33="",Gleba_Dane!B34=""),"",Gleba_Dane!B32*Gleba_Dane!B33*Gleba_Dane!B34) | C9: kg | D9: masa gleby dla 1 ha
A10: Hh_ha | B10: =IF(OR(B8="",B9=""),"",B8*B9/100) | C10: mol(+) | D10: całkowita kwasowość hydrolityczna
A11: CaO | B11: =IF(B10="","",B10*0.028) | C11: kg/ha | D11: zapotrzebowanie na wapno
A12: CaCO3 | B12: =IF(B10="","",B10*0.05) | C12: kg/ha | D12: zapotrzebowanie na wapno
A13: S | B13: =IF(OR(Gleba_Dane!B24="",Gleba_Dane!B25="",Gleba_Dane!B26="",Gleba_Dane!B27=""),"",(Gleba_Dane!B24*Gleba_Dane!B25-Gleba_Dane!B26*Gleba_Dane!B27)*4*5) | C13: mmol(+)/100 g | D13: suma kationów zasadowych
A14: T | B14: =IF(OR(B8="",B13=""),"",B8+B13) | C14: mmol(+)/100 g | D14: pojemność sorpcyjna
A15: Klasa gleby uprawnej | B15: =IF(B7="","Brak danych",IF(B7<=4,"bardzo kwaśne",IF(B7<=4.5,"kwaśne",IF(B7<=5,"średnio kwaśne",IF(B7<=6,"słabo kwaśne",IF(B7<=6.5,"obojętne",IF(B7<=7,"słabo alkaliczne",IF(B7<=7.5,"średnio alkaliczne","alkaliczne")))))))) | D15: klasyfikacja
A16: Klasa gleby leśnej | B16: =IF(B7="","Brak danych",IF(B7<=3.5,"bardzo silnie kwaśne",IF(B7<=4.5,"silnie kwaśne",IF(B7<=5.5,"kwaśne",IF(B7<=6.5,"słabo kwaśne",IF(B7<=7.2,"obojętne",IF(B7<=8,"słabo alkaliczne","alkaliczne"))))))) | D16: klasyfikacja

Sheet Gleba_Wykresy
A1: Gleba - wizualizacje pomocnicze
A2: Wizualizacje pomocnicze
A4: Porównanie pH
A5: Średnie pH wody destylowanej | B5: =Gleba_Wyniki!B5
A6: Średnie pH próbki w wodzie | B6: =Gleba_Wyniki!B6
A7: Średnie pH KCl | B7: =Gleba_Wyniki!B7
A8: Średnie pH próbki w KCl | B8: =Gleba_Wyniki!B8
A12: Hh vs S vs T
A13: Hh | B13: =Gleba_Wyniki!B8
A14: S | B14: =Gleba_Wyniki!B13
A15: T | B15: =Gleba_Wyniki!B14
A19: CaO vs CaCO3
A20: CaO | B20: =Gleba_Wyniki!B11
A21: CaCO3 | B21: =Gleba_Wyniki!B12
